[2025-09-20T10:44:20.229+0200] {taskinstance.py:1103} INFO - Dependencies all met for dep_context=non-requeueable deps ti=<TaskInstance: currency_dag.fetch_currency scheduled__2025-09-19T00:00:00+00:00 [queued]>
[2025-09-20T10:44:20.237+0200] {taskinstance.py:1103} INFO - Dependencies all met for dep_context=requeueable deps ti=<TaskInstance: currency_dag.fetch_currency scheduled__2025-09-19T00:00:00+00:00 [queued]>
[2025-09-20T10:44:20.237+0200] {taskinstance.py:1308} INFO - Starting attempt 1 of 1
[2025-09-20T10:44:20.248+0200] {taskinstance.py:1327} INFO - Executing <Task(PythonOperator): fetch_currency> on 2025-09-19 00:00:00+00:00
[2025-09-20T10:44:20.251+0200] {standard_task_runner.py:57} INFO - Started process 1476 to run task
[2025-09-20T10:44:20.254+0200] {standard_task_runner.py:84} INFO - Running: ['airflow', 'tasks', 'run', 'currency_dag', 'fetch_currency', 'scheduled__2025-09-19T00:00:00+00:00', '--job-id', '6', '--raw', '--subdir', 'DAGS_FOLDER/dag_currency.py', '--cfg-path', '/tmp/tmpk7ani8za']
[2025-09-20T10:44:20.256+0200] {standard_task_runner.py:85} INFO - Job 6: Subtask fetch_currency
[2025-09-20T10:44:20.300+0200] {task_command.py:410} INFO - Running <TaskInstance: currency_dag.fetch_currency scheduled__2025-09-19T00:00:00+00:00 [running]> on host 1102361e702e
[2025-09-20T10:44:20.372+0200] {taskinstance.py:1547} INFO - Exporting env vars: AIRFLOW_CTX_DAG_OWNER='airflow' AIRFLOW_CTX_DAG_ID='currency_dag' AIRFLOW_CTX_TASK_ID='fetch_currency' AIRFLOW_CTX_EXECUTION_DATE='2025-09-19T00:00:00+00:00' AIRFLOW_CTX_TRY_NUMBER='1' AIRFLOW_CTX_DAG_RUN_ID='scheduled__2025-09-19T00:00:00+00:00'
[2025-09-20T10:44:20.376+0200] {taskinstance.py:1824} ERROR - Task failed with exception
Traceback (most recent call last):
  File "/home/airflow/.local/lib/python3.7/site-packages/airflow/operators/python.py", line 181, in execute
    return_value = self.execute_callable()
  File "/home/airflow/.local/lib/python3.7/site-packages/airflow/operators/python.py", line 198, in execute_callable
    return self.python_callable(*self.op_args, **self.op_kwargs)
  File "/opt/airflow/dags/dag_currency.py", line 9, in fetch_currency
    conn = psycopg2.connect("dbname=postgres user=postgres password=postgres host=postgres")
  File "/home/airflow/.local/lib/python3.7/site-packages/psycopg2/__init__.py", line 122, in connect
    conn = _connect(dsn, connection_factory=connection_factory, **kwasync)
psycopg2.OperationalError: connection to server at "postgres" (172.18.0.2), port 5432 failed: FATAL:  password authentication failed for user "postgres"

[2025-09-20T10:44:20.384+0200] {taskinstance.py:1350} INFO - Marking task as FAILED. dag_id=currency_dag, task_id=fetch_currency, execution_date=20250919T000000, start_date=20250920T084420, end_date=20250920T084420
[2025-09-20T10:44:20.393+0200] {standard_task_runner.py:109} ERROR - Failed to execute job 6 for task fetch_currency (connection to server at "postgres" (172.18.0.2), port 5432 failed: FATAL:  password authentication failed for user "postgres"
; 1476)
[2025-09-20T10:44:20.433+0200] {local_task_job_runner.py:225} INFO - Task exited with return code 1
[2025-09-20T10:44:20.449+0200] {taskinstance.py:2653} INFO - 0 downstream tasks scheduled from follow-on schedule check
