[2025-09-20T10:44:21.220+0200] {taskinstance.py:1103} INFO - Dependencies all met for dep_context=non-requeueable deps ti=<TaskInstance: products_dag.load_products scheduled__2025-09-01T00:00:00+00:00 [queued]>
[2025-09-20T10:44:21.226+0200] {taskinstance.py:1103} INFO - Dependencies all met for dep_context=requeueable deps ti=<TaskInstance: products_dag.load_products scheduled__2025-09-01T00:00:00+00:00 [queued]>
[2025-09-20T10:44:21.227+0200] {taskinstance.py:1308} INFO - Starting attempt 1 of 1
[2025-09-20T10:44:21.237+0200] {taskinstance.py:1327} INFO - Executing <Task(PythonOperator): load_products> on 2025-09-01 00:00:00+00:00
[2025-09-20T10:44:21.240+0200] {standard_task_runner.py:57} INFO - Started process 1478 to run task
[2025-09-20T10:44:21.243+0200] {standard_task_runner.py:84} INFO - Running: ['airflow', 'tasks', 'run', 'products_dag', 'load_products', 'scheduled__2025-09-01T00:00:00+00:00', '--job-id', '7', '--raw', '--subdir', 'DAGS_FOLDER/dag_products.py', '--cfg-path', '/tmp/tmpu88f5lqv']
[2025-09-20T10:44:21.245+0200] {standard_task_runner.py:85} INFO - Job 7: Subtask load_products
[2025-09-20T10:44:21.289+0200] {task_command.py:410} INFO - Running <TaskInstance: products_dag.load_products scheduled__2025-09-01T00:00:00+00:00 [running]> on host 1102361e702e
[2025-09-20T10:44:21.371+0200] {taskinstance.py:1547} INFO - Exporting env vars: AIRFLOW_CTX_DAG_OWNER='airflow' AIRFLOW_CTX_DAG_ID='products_dag' AIRFLOW_CTX_TASK_ID='load_products' AIRFLOW_CTX_EXECUTION_DATE='2025-09-01T00:00:00+00:00' AIRFLOW_CTX_TRY_NUMBER='1' AIRFLOW_CTX_DAG_RUN_ID='scheduled__2025-09-01T00:00:00+00:00'
[2025-09-20T10:44:21.376+0200] {taskinstance.py:1824} ERROR - Task failed with exception
Traceback (most recent call last):
  File "/home/airflow/.local/lib/python3.7/site-packages/airflow/operators/python.py", line 181, in execute
    return_value = self.execute_callable()
  File "/home/airflow/.local/lib/python3.7/site-packages/airflow/operators/python.py", line 198, in execute_callable
    return self.python_callable(*self.op_args, **self.op_kwargs)
  File "/opt/airflow/dags/dag_products.py", line 14, in load_products
    conn = psycopg2.connect("dbname=postgres user=postgres password=postgres host=postgres")
  File "/home/airflow/.local/lib/python3.7/site-packages/psycopg2/__init__.py", line 122, in connect
    conn = _connect(dsn, connection_factory=connection_factory, **kwasync)
psycopg2.OperationalError: connection to server at "postgres" (172.18.0.2), port 5432 failed: FATAL:  password authentication failed for user "postgres"

[2025-09-20T10:44:21.387+0200] {taskinstance.py:1350} INFO - Marking task as FAILED. dag_id=products_dag, task_id=load_products, execution_date=20250901T000000, start_date=20250920T084421, end_date=20250920T084421
[2025-09-20T10:44:21.398+0200] {standard_task_runner.py:109} ERROR - Failed to execute job 7 for task load_products (connection to server at "postgres" (172.18.0.2), port 5432 failed: FATAL:  password authentication failed for user "postgres"
; 1478)
[2025-09-20T10:44:21.428+0200] {local_task_job_runner.py:225} INFO - Task exited with return code 1
[2025-09-20T10:44:21.448+0200] {taskinstance.py:2653} INFO - 0 downstream tasks scheduled from follow-on schedule check
