[2025-09-20T10:44:22.355+0200] {taskinstance.py:1103} INFO - Dependencies all met for dep_context=non-requeueable deps ti=<TaskInstance: sales_generated_dag.generate_sales scheduled__2025-09-19T00:00:00+00:00 [queued]>
[2025-09-20T10:44:22.363+0200] {taskinstance.py:1103} INFO - Dependencies all met for dep_context=requeueable deps ti=<TaskInstance: sales_generated_dag.generate_sales scheduled__2025-09-19T00:00:00+00:00 [queued]>
[2025-09-20T10:44:22.364+0200] {taskinstance.py:1308} INFO - Starting attempt 1 of 1
[2025-09-20T10:44:22.383+0200] {taskinstance.py:1327} INFO - Executing <Task(PythonOperator): generate_sales> on 2025-09-19 00:00:00+00:00
[2025-09-20T10:44:22.391+0200] {standard_task_runner.py:57} INFO - Started process 1488 to run task
[2025-09-20T10:44:22.397+0200] {standard_task_runner.py:84} INFO - Running: ['airflow', 'tasks', 'run', 'sales_generated_dag', 'generate_sales', 'scheduled__2025-09-19T00:00:00+00:00', '--job-id', '9', '--raw', '--subdir', 'DAGS_FOLDER/dag_sales_generated.py', '--cfg-path', '/tmp/tmp42hol3q7']
[2025-09-20T10:44:22.399+0200] {standard_task_runner.py:85} INFO - Job 9: Subtask generate_sales
[2025-09-20T10:44:22.460+0200] {task_command.py:410} INFO - Running <TaskInstance: sales_generated_dag.generate_sales scheduled__2025-09-19T00:00:00+00:00 [running]> on host 1102361e702e
[2025-09-20T10:44:22.532+0200] {taskinstance.py:1547} INFO - Exporting env vars: AIRFLOW_CTX_DAG_OWNER='airflow' AIRFLOW_CTX_DAG_ID='sales_generated_dag' AIRFLOW_CTX_TASK_ID='generate_sales' AIRFLOW_CTX_EXECUTION_DATE='2025-09-19T00:00:00+00:00' AIRFLOW_CTX_TRY_NUMBER='1' AIRFLOW_CTX_DAG_RUN_ID='scheduled__2025-09-19T00:00:00+00:00'
[2025-09-20T10:44:22.536+0200] {taskinstance.py:1824} ERROR - Task failed with exception
Traceback (most recent call last):
  File "/home/airflow/.local/lib/python3.7/site-packages/airflow/operators/python.py", line 181, in execute
    return_value = self.execute_callable()
  File "/home/airflow/.local/lib/python3.7/site-packages/airflow/operators/python.py", line 198, in execute_callable
    return self.python_callable(*self.op_args, **self.op_kwargs)
  File "/opt/airflow/dags/dag_sales_generated.py", line 8, in generate_sales
    conn = psycopg2.connect("dbname=postgres user=postgres password=postgres host=postgres")
  File "/home/airflow/.local/lib/python3.7/site-packages/psycopg2/__init__.py", line 122, in connect
    conn = _connect(dsn, connection_factory=connection_factory, **kwasync)
psycopg2.OperationalError: connection to server at "postgres" (172.18.0.2), port 5432 failed: FATAL:  password authentication failed for user "postgres"

[2025-09-20T10:44:22.546+0200] {taskinstance.py:1350} INFO - Marking task as FAILED. dag_id=sales_generated_dag, task_id=generate_sales, execution_date=20250919T000000, start_date=20250920T084422, end_date=20250920T084422
[2025-09-20T10:44:22.555+0200] {standard_task_runner.py:109} ERROR - Failed to execute job 9 for task generate_sales (connection to server at "postgres" (172.18.0.2), port 5432 failed: FATAL:  password authentication failed for user "postgres"
; 1488)
[2025-09-20T10:44:22.577+0200] {local_task_job_runner.py:225} INFO - Task exited with return code 1
[2025-09-20T10:44:22.596+0200] {taskinstance.py:2653} INFO - 0 downstream tasks scheduled from follow-on schedule check
