[2025-09-20T10:44:19.999+0200] {taskinstance.py:1103} INFO - Dependencies all met for dep_context=non-requeueable deps ti=<TaskInstance: competitors_dag.fetch_competitors scheduled__2025-09-19T00:00:00+00:00 [queued]>
[2025-09-20T10:44:20.006+0200] {taskinstance.py:1103} INFO - Dependencies all met for dep_context=requeueable deps ti=<TaskInstance: competitors_dag.fetch_competitors scheduled__2025-09-19T00:00:00+00:00 [queued]>
[2025-09-20T10:44:20.007+0200] {taskinstance.py:1308} INFO - Starting attempt 1 of 1
[2025-09-20T10:44:20.018+0200] {taskinstance.py:1327} INFO - Executing <Task(PythonOperator): fetch_competitors> on 2025-09-19 00:00:00+00:00
[2025-09-20T10:44:20.023+0200] {standard_task_runner.py:57} INFO - Started process 1475 to run task
[2025-09-20T10:44:20.026+0200] {standard_task_runner.py:84} INFO - Running: ['airflow', 'tasks', 'run', 'competitors_dag', 'fetch_competitors', 'scheduled__2025-09-19T00:00:00+00:00', '--job-id', '5', '--raw', '--subdir', 'DAGS_FOLDER/dag_competitors.py', '--cfg-path', '/tmp/tmphws6u2gj']
[2025-09-20T10:44:20.028+0200] {standard_task_runner.py:85} INFO - Job 5: Subtask fetch_competitors
[2025-09-20T10:44:20.092+0200] {task_command.py:410} INFO - Running <TaskInstance: competitors_dag.fetch_competitors scheduled__2025-09-19T00:00:00+00:00 [running]> on host 1102361e702e
[2025-09-20T10:44:20.183+0200] {taskinstance.py:1547} INFO - Exporting env vars: AIRFLOW_CTX_DAG_OWNER='airflow' AIRFLOW_CTX_DAG_ID='competitors_dag' AIRFLOW_CTX_TASK_ID='fetch_competitors' AIRFLOW_CTX_EXECUTION_DATE='2025-09-19T00:00:00+00:00' AIRFLOW_CTX_TRY_NUMBER='1' AIRFLOW_CTX_DAG_RUN_ID='scheduled__2025-09-19T00:00:00+00:00'
[2025-09-20T10:44:20.187+0200] {taskinstance.py:1824} ERROR - Task failed with exception
Traceback (most recent call last):
  File "/home/airflow/.local/lib/python3.7/site-packages/airflow/operators/python.py", line 181, in execute
    return_value = self.execute_callable()
  File "/home/airflow/.local/lib/python3.7/site-packages/airflow/operators/python.py", line 198, in execute_callable
    return self.python_callable(*self.op_args, **self.op_kwargs)
  File "/opt/airflow/dags/dag_competitors.py", line 9, in fetch_competitors
    conn = psycopg2.connect("dbname=postgres user=postgres password=postgres host=postgres")
  File "/home/airflow/.local/lib/python3.7/site-packages/psycopg2/__init__.py", line 122, in connect
    conn = _connect(dsn, connection_factory=connection_factory, **kwasync)
psycopg2.OperationalError: connection to server at "postgres" (172.18.0.2), port 5432 failed: FATAL:  password authentication failed for user "postgres"

[2025-09-20T10:44:20.196+0200] {taskinstance.py:1350} INFO - Marking task as FAILED. dag_id=competitors_dag, task_id=fetch_competitors, execution_date=20250919T000000, start_date=20250920T084420, end_date=20250920T084420
[2025-09-20T10:44:20.206+0200] {standard_task_runner.py:109} ERROR - Failed to execute job 5 for task fetch_competitors (connection to server at "postgres" (172.18.0.2), port 5432 failed: FATAL:  password authentication failed for user "postgres"
; 1475)
[2025-09-20T10:44:20.246+0200] {local_task_job_runner.py:225} INFO - Task exited with return code 1
[2025-09-20T10:44:20.265+0200] {taskinstance.py:2653} INFO - 0 downstream tasks scheduled from follow-on schedule check
